Workbook
Name ANALYSIS_DATE: Trading_comps!$D$4
Name BETA: '1'!$C$20
Name BETA: '2'!$C$20
Name BETA: '3'!$C$20
Name CASH_AND_ST_INVESTMENTS: '1'!$H$8
Name CASH_AND_ST_INVESTMENTS: '2'!$H$8
Name CASH_AND_ST_INVESTMENTS: '3'!$H$8
Name Circswitch: Info!$N$10
Name COMP_CALENDARIZE_PERCENTAGES: '1'!$I$79:$K$79
Name COMP_CALENDARIZE_PERCENTAGES: '2'!$I$79:$K$79
Name COMP_CALENDARIZE_PERCENTAGES: '3'!$I$79:$K$79
Name COMP_CALENDARIZE_PERCENTAGES: 'Factset codes'!$R$64:$V$64
Name COMP_EQ_VALUE: '1'!$H$6
Name COMP_EQ_VALUE: '2'!$H$6
Name COMP_EQ_VALUE: '3'!$H$6
Name COMP_EQ_VALUE: 'Factset codes'!$R$10
Name COMP_EV: '1'!$H$10
Name COMP_EV: '2'!$H$10
Name COMP_EV: '3'!$H$10
Name COMP_EV: 'Factset codes'!$L$10
Name COMP_FX: '1'!$C$15
Name COMP_FX: '2'!$C$15
Name COMP_FX: '3'!$C$15
Name COMP_MTR: '1'!$C$10
Name COMP_MTR: '2'!$C$10
Name COMP_MTR: '3'!$C$10
Name Comp_MTR: 'Factset codes'!$D$19
Name COMP_SHAREPRICE: '1'!$C$16
Name COMP_SHAREPRICE: '2'!$C$16
Name COMP_SHAREPRICE: '3'!$C$16
Name COMP_SHAREPRICE: 'Factset codes'!$D$13
Name COMPANY_NAME: '1'!$A$1
Name COMPANY_NAME: '2'!$A$1
Name COMPANY_NAME: '3'!$A$1
Name CREDIT_RATING: '1'!$C$19
Name CREDIT_RATING: '2'!$C$19
Name CREDIT_RATING: '3'!$C$19
Name DSO: '1'!$D$35
Name DSO: '2'!$D$35
Name DSO: '3'!$D$35
Name EBIT_CY1: '1'!$H$16
Name EBIT_CY1: '2'!$H$16
Name EBIT_CY1: '3'!$H$16
Name EBIT_CY2: '1'!$I$16
Name EBIT_CY2: '2'!$I$16
Name EBIT_CY2: '3'!$I$16
Name EBIT_CY3: '1'!$J$16
Name EBIT_CY3: '2'!$J$16
Name EBIT_CY3: '3'!$J$16
Name EBIT_CY4: '1'!$K$16
Name EBIT_CY4: '2'!$K$16
Name EBIT_CY4: '3'!$K$16
Name EBIT_LTM: '1'!$G$16
Name EBIT_LTM: '2'!$G$16
Name EBIT_LTM: '3'!$G$16
Name EBIT_LTM: 'Factset codes'!$J$14
Name EBITDA_CY1: '1'!$H$15
Name EBITDA_CY1: '2'!$H$15
Name EBITDA_CY1: '3'!$H$15
Name EBITDA_CY2: '1'!$I$15

Sheet Info
A1: Red Bull GmbH — Valuation & M&A Analysis
A2: Confidential — For Discussion Purposes Only
B4: Table of Contents | L4: Model Details
B5: # | C5: Tab | E5: Description | L5: Company | N5: Red Bull
B6: 1 | C6: Red Bull Model | E6: 3-statement financial forecast (IS / BS / CF) | L6: Analysis Date | N6: 46077
B7: 2 | C7: WACC | E7: Weighted average cost of capital | L7: Currency | N7: EUR / USD (as noted)
B8: 3 | C8: DCF | E8: Discounted cash flow valuation | L8: Units | N8: Millions
B9: 4 | C9: Trading Comps | E9: Public company comparable analysis | L9: Analyst | N9: Amgad Bashir
C10: 1 / 2 / 3 | E10: Individual company tearsheets | L10: Circular Switch | N10: 1
B11: 5 | C11: Transaction Comps | E11: Precedent transaction analysis
B12: 6 | C12: Valuation Summary | E12: Football field — consolidated valuation ranges | L12: Color Legend
B13: 7 | C13: Synergies | E13: Synergy value DCF analysis | L13: 123 | N13: Input cell — hardcoded assumption
B14: 8 | C14: M&A | E14: Acquisition scenario — accretion / dilution | L14: 123 | N14: Hardcoded value (no input shading)
B15: 9 | C15: LBO | E15: Leveraged buyout — IRR sensitivity | L15: 123 | N15: Formula / calculation
L16: 123 | N16: Cross-sheet link
L17: 123 | N17: Key assumption — review required

Sheet Red Bull Model
A1: ="Financial forecast for "&Info!N5 -> Financial forecast for Red Bull
C2: Actual | D2: Actual | E2: Actual | F2: Actual | G2: Actual / Est. | H2: Actual / Est. | I2: Projected | J2: Projected | K2: Projected | L2: Projected | M2: Projected | N2: Projected | O2: Projected | P2: Projected
C3: =EDATE(D3,-12) -> 44196 | D3: =EDATE(E3,-12) -> 44561 | E3: =EDATE(F3,-12) -> 44926 | F3: =EDATE(G3,-12) -> 45291 | G3: =EDATE(H3,-12) -> 45657 | H3: 46022 | I3: =EDATE(H3,12) -> 46387 | J3: =EDATE(I3,12) -> 46752 | K3: =EDATE(J3,12) -> 47118 | L3: =EDATE(K3,12) -> 47483 | M3: =EDATE(L3,12) -> 47848 | N3: =EDATE(M3,12) -> 48213 | O3: =EDATE(N3,12) -> 48579 | P3: =EDATE(O3,12) -> 48944
B4: All numbers in EURm unless otherwise stated
A6: Assumptions
B8: Revenue growth - Europe | D8: =D50/C50-1 -> 0.25744369 | E8: =E50/D50-1 -> 0.24401562 | F8: =F50/E50-1 -> 0.090999999 | G8: =G50/F50-1 -> 0.063768479 | H8: =H50/G50-1 -> 0.086309789 | I8: 0.085 | J8: 0.08 | K8: 0.075 | L8: 0.07 | M8: 0.065 | N8: 0.05 | O8: 0.03 | P8: 0.026
B9: Revenue growth - USA | D9: =D51/C51-1 -> 0.2166617 | E9: =E51/D51-1 -> 0.1787136 | F9: =F51/E51-1 -> 0.065999999 | G9: =G51/F51-1 -> 0.063768479 | H9: =H51/G51-1 -> 0.086309789 | I9: 0.075 | J9: 0.075 | K9: 0.07 | L9: 0.07 | M9: 0.065 | N9: 0.05 | O9: 0.03 | P9: 0.026
B10: Revenue growth - Americas excluding USA | D10: =D52/C52-1 -> 0.37622812 | E10: =E52/D52-1 -> 0.68187426 | F10: =F52/E52-1 -> 0.21999999 | G10: =G52/F52-1 -> 0.063768479 | H10: =H52/G52-1 -> 0.086309789 | I10: 0.15 | J10: 0.13 | K10: 0.11 | L10: 0.1 | M10: 0.08 | N10: 0.07 | O10: 0.05 | P10: 0.026
B11: Revenue growth - Rest of world | D11: =D53/C53-1 -> 0.21058521 | E11: =E53/D53-1 -> 0.23555449 | F11: =F53/E53-1 -> 0.084999996 | G11: =G53/F53-1 -> 0.063768479 | H11: =H53/G53-1 -> 0.086309789 | I11: 0.085 | J11: 0.082 | K11: 0.08 | L11: 0.08 | M11: 0.07 | N11: 0.055 | O11: 0.035 | P11: 0.026
B12: Total revenue growth | D12: =D54/C54-1 -> 0.23914094 | E12: =E54/D54-1 -> 0.23908278 | F12: =F54/E54-1 -> 0.08981377 | G12: =G54/F54-1 -> 0.063768479 | H12: =H54/G54-1 -> 0.086309789 | I12: =I54/H54-1 -> 0.086622267 | J12: =J54/I54-1 -> 0.082925779 | K12: =K54/J54-1 -> 0.076975775 | ... P12: =P54/O54-1 -> 0.026
B13: Total revenue check, CAGR 2024-2029 | M13: =(M54/H54)^(1/COLUMNS(I54:M54))-1 -> 0.077566836
B14: COGS as % of total revenue | C14: =-C55/C54 -> 0.27524088 | D14: =-D55/D54 -> 0.28381392 | E14: =-E55/E54 -> 0.3365439 | F14: =-F55/F54 -> 0.32733715 | G14: =-G55/G54 -> 0.32733715 | H14: =-H55/H54 -> 0.32733715 | I14: 0.32 | J14: 0.315 | K14: 0.31 | L14: 0.31 | M14: 0.31 | N14: 0.31 | O14: 0.31 | P14: 0.31
B15: SG&A as % of total revenue | C15: =-C58/C54 -> 0.16004422 | D15: =-D58/D54 -> 0.15133323 | E15: =-E58/E54 -> 0.14988937 | F15: =-F58/F54 -> 0.14578888 | G15: 0.145 | H15: 0.143 | I15: 0.142 | J15: 0.14 | K15: 0.138 | L15: 0.138 | M15: 0.138 | N15: 0.138 | O15: 0.138 | P15: 0.138
B16: Marketing expense as % of total revenue | C16: =-C59/C54 -> 0.25769865 | D16: =-D59/D54 -> 0.23826758 | E16: =-E59/E54 -> 0.23638673 | F16: =-F59/F54 -> 0.22991995 | G16: 0.227 | H16: 0.225 | I16: 0.223 | J16: 0.22 | K16: 0.218 | L16: 0.218 | M16: 0.218 | N16: 0.218 | O16: 0.218 | P16: 0.218
B17: Depreciation % beginning net PP&E | D17: =-D62/C80 -> 0.17934716 | E17: =-E62/D80 -> 0.20397502 | F17: =-F62/E80 -> 0.17411863 | G17: 0.17 | H17: 0.17 | I17: 0.17 | J17: 0.17 | K17: 0.17 | L17: 0.16 | M17: 0.16 | N17: 0.16 | O17: 0.16 | P17: 0.16
B18: Other financial income / expense amount | C18: =C67 -> 7.6356352 | D18: =D67 -> 4.348142 | E18: =E67 -> 7.239741 | F18: =F67 -> 7 | G18: 7.5 | H18: 7.5 | I18: 7.5 | J18: 7.5 | K18: 7.5 | L18: 7.5 | M18: 7.5 | N18: 7.5 | O18: 7.5 | P18: 7.5
B19: Effective tax rate | C19: =-C70/C68 -> 0.25736781 | D19: =-D70/D68 -> 0.25534236 | E19: =-E70/E68 -> 0.25835485 | F19: =-F70/F68 -> 0.22162687 | G19: 0.255 | H19: 0.255 | I19: 0.255 | J19: 0.255 | K19: 0.255 | L19: 0.255 | M19: 0.255 | N19: 0.255 | O19: 0.255 | P19: 0.255
B20: Marginal tax rate | F20: 0.24 | G20: 0.23 | H20: 0.23 | I20: 0.23 | J20: 0.23 | K20: 0.23 | L20: 0.23 | M20: 0.23 | N20: 0.23 | O20: 0.23 | P20: 0.23
B21: Dividend payout ratio % net income | D21: =+D45/D71*-1 -> 0.71258993 | E21: =+E45/E71*-1 -> 0.87774617 | F21: =+F45/F71*-1 -> 0.7912551 | G21: 0.6 | H21: 0.75 | I21: 0.75 | J21: 0.75 | K21: 0.75 | L21: 0.75 | M21: 0.75 | N21: 0.75 | O21: 0.75 | P21: 0.75
B23: Accounts receivable days | C23: =+C75/C54*365 -> 39.12377 | D23: =+D75/D54*365 -> 36.539804 | E23: =+E75/E54*365 -> 41.077387 | F23: =+F75/F54*365 -> 39.979199 | G23: 40 | H23: 40 | I23: 39 | J23: 39 | K23: 39 | L23: 39 | M23: 39 | N23: 39 | O23: 39 | P23: 39
B24: Inventory days | C24: =-C76/C55*365 -> 92.813518 | D24: =-D76/D55*365 -> 78.431642 | E24: =-E76/E55*365 -> 104.66439 | F24: =-F76/F55*365 -> 89.995045 | G24: 90 | H24: 90 | I24: 89 | J24: 90 | K24: 90 | L24: 90 | M24: 90 | N24: 90 | O24: 90 | P24: 90
B25: Other current assets as % of total revenue | C25: =+C77/C54 -> 0.056305307 | D25: =+D77/D54 -> 0.051816294 | E25: =+E77/E54 -> 0.060473152 | F25: =+F77/F54 -> 0.0519993 | G25: 0.053 | H25: 0.053 | I25: 0.052 | J25: 0.052 | K25: 0.051 | L25: 0.051 | M25: 0.051 | N25: 0.051 | O25: 0.051 | P25: 0.051
B26: Capital expenditure % of total revenue | C26: =C38/C54 -> 0.059327908 | D26: =D38/D54 -> 0.069950089 | E26: =E38/E54 -> 0.06828807 | F26: =F38/F54 -> 0.075772304 | G26: 0.068 | H26: 0.068 | I26: 0.068 | J26: 0.062 | K26: 0.062 | L26: 0.062 | M26: 0.055 | N26: 0.055 | O26: 0.051 | P26: 0.051
B27: Financial assets amount | C27: =+C81 -> 523.84919 | D27: =+D81 -> 751.47739 | E27: =+E81 -> 1162.6034 | F27: =+F81 -> 1205.8 | G27: 1200 | H27: 1200 | I27: 1200 | J27: 1200 | K27: 1200 | L27: 1200 | M27: 1200 | N27: 1200 | O27: 1200 | P27: 1200
B28: Accounts payable days | C28: =-C85/C55*365 -> 252.23162 | D28: =-D85/D55*365 -> 261.46575 | E28: =-E85/E55*365 -> 245.70742 | F28: =-F85/F55*365 -> 250.99933 | G28: 259 | H28: 259 | I28: 259 | J28: 259 | K28: 259 | L28: 259 | M28: 259 | N28: 259 | O28: 259 | P28: 259
B30: Long term debt issuance (repayment) | D30: =D88-C88 -> 5.9601356 | E30: =E88-D88 -> 40.856667 | F30: =F88-E88 -> -21.216398 | G30: 0 | H30: -11.2 | I30: 0 | J30: 0 | K30: 0 | L30: 0 | M30: 0 | N30: 0 | O30: 0 | P30: 0
B31: Interest rate on revolver | G31: 0.05 | H31: 0.04 | I31: 0.04 | J31: 0.032 | K31: 0.032 | L31: 0.032 | M31: 0.032 | N31: 0.032 | O31: 0.032 | P31: 0.032
B32: Interest rate on long term debt | G32: 0.06 | H32: 0.06 | I32: 0.06 | J32: 0.06 | K32: 0.06 | L32: 0.06 | M32: 0.06 | N32: 0.06 | O32: 0.06 | P32: 0.06
B33: Interest rate on cash | G33: 0.038 | H33: 0.03 | I33: 0.03 | J33: 0.022 | K33: 0.022 | L33: 0.022 | M33: 0.022 | N33: 0.022 | O33: 0.022 | P33: 0.022
A35: Calculations
B36: Net PP&E
B37: Beginning | G37: =F40 -> 2601.2 | H37: =G40 -> 2922.432 | I37: =H40 -> 3254.9466 | J37: =I40 -> 3602.7719 | K37: =J40 -> 3880.0884 | L37: =K40 -> 4178.7532 | M37: =L40 -> 4539.5859 | N37: =M40 -> 4787.7956 | ... P37: =O40 -> 5222.5285
B38: Capital expenditure | C38: 374.19874 | D38: 546.70401 | E38: 661.31618 | F38: 799.7 | G38: =G26*G54 -> 763.436 | H38: =H26*H54 -> 829.328 | I38: =I26*I54 -> 901.16627 | J38: =J26*J54 -> 889.7877 | K38: =K26*K54 -> 958.2798 | L38: =L26*L54 -> 1029.4333 | M38: =M26*M54 -> 974.54341 | N38: =N26*N54 -> 1025.9269 | ... P38: =P26*P54 -> 1008.0259
B39: Depreciation | G39: =G17*G37*-1 -> -442.204 | H39: =H17*H37*-1 -> -496.81344 | I39: =I17*I37*-1 -> -553.34092 | J39: =J17*J37*-1 -> -612.47123 | K39: =K17*K37*-1 -> -659.61503 | L39: =L17*L37*-1 -> -668.60051 | M39: =M17*M37*-1 -> -726.33375 | N39: =N17*N37*-1 -> -766.04729 | ... P39: =P17*P37*-1 -> -835.60457
B40: Ending | F40: =F80 -> 2601.2 | G40: =SUM(G37:G39) -> 2922.432 | H40: =SUM(H37:H39) -> 3254.9466 | I40: =SUM(I37:I39) -> 3602.7719 | J40: =SUM(J37:J39) -> 3880.0884 | K40: =SUM(K37:K39) -> 4178.7532 | L40: =SUM(L37:L39) -> 4539.5859 | M40: =SUM(M37:M39) -> 4787.7956 | N40: =SUM(N37:N39) -> 5047.6752 | ... P40: =SUM(P37:P39) -> 5394.9498
B42: Equity
B43: Beginning | G43: =F46 -> 4112.4 | H43: =G46 -> 4990.5842 | I43: =H46 -> 5593.7631 | J43: =I46 -> 6273.5727 | K43: =J46 -> 7032.6984 | L43: =K46 -> 7877.741 | M43: =L46 -> 8794.6556 | N43: =M46 -> 9772.7599 | ... P43: =O46 -> 11870.076
B44: Net income | G44: =G71 -> 2195.4604 | H44: =H71 -> 2412.7158 | I44: =I71 -> 2719.2384 | J44: =J71 -> 3036.5028 | K44: =K71 -> 3380.1703 | L44: =L71 -> 3667.6582 | M44: =M71 -> 3912.4175 | N44: =N71 -> 4127.3666 | ... P44: =P71 -> 4380.4176
B45: Dividends | D45: -1220.1393 | E45: -1510.7227 | F45: -1701 | G45: =G21*G44*-1 -> -1317.2762 | H45: =H21*H44*-1 -> -1809.5369 | I45: =I21*I44*-1 -> -2039.4288 | J45: =J21*J44*-1 -> -2277.3771 | K45: =K21*K44*-1 -> -2535.1277 | L45: =L21*L44*-1 -> -2750.7437 | M45: =M21*M44*-1 -> -2934.3131 | N45: =N21*N44*-1 -> -3095.525 | ... P45: =P21*P44*-1 -> -3285.3132
B46: Ending | F46: =F91 -> 4112.4 | G46: =SUM(G43:G45) -> 4990.5842 | H46: =SUM(H43:H45) -> 5593.7631 | I46: =SUM(I43:I45) -> 6273.5727 | J46: =SUM(J43:J45) -> 7032.6984 | K46: =SUM(K43:K45) -> 7877.741 | L46: =SUM(L43:L45) -> 8794.6556 | M46: =SUM(M43:M45) -> 9772.7599 | N46: =SUM(N43:N45) -> 10804.602 | ... P46: =SUM(P43:P45) -> 12965.181
...

Sheet WACC
A1: ="Weighted average cost of capital for "&Info!N5 -> Weighted average cost of capital for Red Bull
A2: All figures in USDm unless otherwise stated
F4: Total | G4: Debt / | H4: Historical | I4: Credit | K4: Debt % | L4: Debt % | M4: Unlevered
C5: Company | D5: Ticker | E5: Market Cap | F5: Debt | G5: LTM EBITDA | H5: Beta | I5: Rating | J5: MTR | K5: Capital | L5: Equity | M5: Beta
B7: 1 | C7: =Trading_comps!C11 -> Coca-Cola Company | D7: =Trading_comps!BH11 -> KO-US | E7: =Trading_comps!G11 -> 344591.76 | F7: =Trading_comps!BG11 -> 45492 | G7: =Trading_comps!BD11 -> 2.8320986 | H7: =Trading_comps!BE11 -> 0.57 | I7: =Trading_comps!BF11 -> A+ | J7: 0.21 | K7: =F7/(F7+E7) -> 0.11662111 | L7: =K7/(1-K7) -> 0.13201708 | M7: =H7/(1+(1-J7)*L7) -> 0.51616713
B8: 2 | C8: =Trading_comps!C12 -> Keurig Dr Pepper | D8: =Trading_comps!BH12 -> KDP-US | E8: =Trading_comps!G12 -> 40504.205 | F8: =Trading_comps!BG12 -> 16839 | G8: =Trading_comps!BD12 -> 3.7172185 | H8: =Trading_comps!BE12 -> 0.55 | I8: =Trading_comps!BF12 -> BBB | J8: 0.21 | K8: =F8/(F8+E8) -> 0.29365293 | L8: =K8/(1-K8) -> 0.41573461 | M8: =H8/(1+(1-J8)*L8) -> 0.41402246
B9: 3 | C9: =Trading_comps!C13 -> Monster Beverage | D9: =Trading_comps!BH13 -> MNST-US | E9: =Trading_comps!G13 -> 83024.655 | F9: =Trading_comps!BG13 -> 0 | G9: =Trading_comps!BD13 -> 0 | H9: =Trading_comps!BE13 -> 0.63 | I9: =Trading_comps!BF13 -> N/A | J9: 0.21 | K9: =F9/(F9+E9) -> 0 | L9: =K9/(1-K9) -> 0 | M9: =H9/(1+(1-J9)*L9) -> 0.63
B10: 4 | C10: =Trading_comps!C14 -> PepsiCo | D10: =Trading_comps!BH14 -> PEP-US | E10: =Trading_comps!G14 -> 226465.5 | F10: =Trading_comps!BG14 -> 49182 | G10: =Trading_comps!BD14 -> 2.6783205 | H10: =Trading_comps!BE14 -> 0.6 | I10: =Trading_comps!BF14 -> A+ | J10: 0.21 | K10: =F10/(F10+E10) -> 0.17842353 | L10: =K10/(1-K10) -> 0.21717215 | M10: =H10/(1+(1-J10)*L10) -> 0.51213504
B11: 7 | C11: =Trading_comps!C17 -> Fevertree Drinks | D11: =Trading_comps!BH17 -> FEVR-GB | E11: =Trading_comps!G17 -> 1350 | F11: =Trading_comps!BG17 -> 0 | G11: =Trading_comps!BD17 -> 0 | H11: =Trading_comps!BE17 -> 1.100264 | I11: =Trading_comps!BF17 -> N/A | J11: 0.25 | K11: =F11/(F11+E11) -> 0 | L11: =K11/(1-K11) -> 0 | M11: =H11/(1+(1-J11)*L11) -> 1.100264
C13: Industry average | K13: =AVERAGE(K7:K11) -> 0.11773951 | M13: =AVERAGE(M7:M11) -> 0.63451773
C17: Risk free rate | D17: 0.027
C18: Market risk premium (incl. country risk premium) | D18: =4.23%+0.35% -> 0.0458
C19: Industry average unlevered beta | D19: =M13 -> 0.63451773
C20: Red Bull MTR | D20: ='Red Bull Model'!G20 -> 0.23
C21: Industry average implied debt % of equity | D21: =K13/(1-K13) -> 0.1334521
C22: Relevered beta | D22: =D19*(1+D21*(1-D20)) -> 0.69971957
C23: Cost of equity | D23: =D17+D18*D22 -> 0.059047156
C24: Equity % of capital | D24: =1-K13 -> 0.88226049
C26: Corporate spread | D26: 0.0118
C27: Cost of debt | D27: =D26+D17 -> 0.0388
C28: After tax cost of debt | D28: =D27*(1-D20) -> 0.029876
C29: Debt % of capital | D29: =K13 -> 0.11773951
C31: WACC | D31: =D23*D24+D28*D29 -> 0.055612559
A33: End

Sheet DCF
A1: ="Discounted cashflow valuation for "&Info!N5 -> Discounted cashflow valuation for Red Bull
C2: ='Red Bull Model'!C2 -> Actual | D2: ='Red Bull Model'!D2 -> Actual | E2: ='Red Bull Model'!E2 -> Actual | F2: ='Red Bull Model'!F2 -> Actual | G2: ='Red Bull Model'!G2 -> Actual / Est. | H2: ='Red Bull Model'!H2 -> Actual / Est. | I2: ='Red Bull Model'!I2 -> Projected | J2: ='Red Bull Model'!J2 -> Projected | ... P2: ='Red Bull Model'!P2 -> Projected
C3: ='Red Bull Model'!C3 -> 44196 | D3: =EDATE(C3,12) -> 44561 | E3: =EDATE(D3,12) -> 44926 | F3: =EDATE(E3,12) -> 45291 | G3: =EDATE(F3,12) -> 45657 | H3: =EDATE(G3,12) -> 46022 | I3: =EDATE(H3,12) -> 46387 | J3: =EDATE(I3,12) -> 46752 | K3: =EDATE(J3,12) -> 47118 | ... P3: =EDATE(O3,12) -> 48944
A4: All numbers in EURm unless otherwise stated
A6: Free cash flows
B7: EBITDA | C7: ='Red Bull Model'!C60 -> 1936.4426 | D7: ='Red Bull Model'!D60 -> 2552.4696 | E7: ='Red Bull Model'!E60 -> 2684.2701 | F7: ='Red Bull Model'!F60 -> 3134.0492 | G7: ='Red Bull Model'!G60 -> 3375.5418 | H7: ='Red Bull Model'!H60 -> 3715.6681 | I7: ='Red Bull Model'!I60 -> 4174.5202 | J7: ='Red Bull Model'!J60 -> 4664.2097 | ... P7: ='Red Bull Model'!P60 -> 6601.5812
B8: EBIT | C8: ='Red Bull Model'!C63 -> 1622.2215 | D8: ='Red Bull Model'!D63 -> 2262.9888 | E8: ='Red Bull Model'!E63 -> 2291.5549 | F8: ='Red Bull Model'!F63 -> 2734.0492 | G8: ='Red Bull Model'!G63 -> 2933.3378 | H8: ='Red Bull Model'!H63 -> 3218.8547 | I8: ='Red Bull Model'!I63 -> 3621.1793 | J8: ='Red Bull Model'!J63 -> 4051.7385 | ... P8: ='Red Bull Model'!P63 -> 5765.9766
B9: Long-term effective tax rate | C9: ='Red Bull Model'!C19 -> 0.25736781 | D9: ='Red Bull Model'!D19 -> 0.25534236 | E9: ='Red Bull Model'!E19 -> 0.25835485 | F9: ='Red Bull Model'!F19 -> 0.22162687 | G9: ='Red Bull Model'!G19 -> 0.255 | H9: ='Red Bull Model'!H19 -> 0.255 | I9: ='Red Bull Model'!I19 -> 0.255 | J9: ='Red Bull Model'!J19 -> 0.255 | ... P9: ='Red Bull Model'!P19 -> 0.255
B11: Net operating profit after tax (NOPAT) | E11: =E8*(1-E9) -> 1699.5206 | F11: =F8*(1-F9) -> 2128.1104 | G11: =G8*(1-G9) -> 2185.3367 | H11: =H8*(1-H9) -> 2398.0467 | I11: =I8*(1-I9) -> 2697.7786 | J11: =J8*(1-J9) -> 3018.5452 | K11: =K8*(1-K9) -> 3354.5346 | L11: =L8*(1-L9) -> 3633.4068 | ... P11: =P8*(1-P9) -> 4295.6526
B12: Depreciation & amortization | I12: ='Red Bull Model'!I98 -> 553.34092 | J12: ='Red Bull Model'!J98 -> 612.47123 | K12: ='Red Bull Model'!K98 -> 659.61503 | L12: ='Red Bull Model'!L98 -> 668.60051 | M12: ='Red Bull Model'!M98 -> 726.33375 | N12: ='Red Bull Model'!N98 -> 766.04729 | O12: ='Red Bull Model'!O98 -> 807.62803 | P12: ='Red Bull Model'!P98 -> 835.60457
B13: (Increase) decrease in operating working capital | I13: =SUM('Red Bull Model'!I99:I102) -> 4.5079714 | J13: =SUM('Red Bull Model'!J99:J102) -> -56.585502 | K13: =SUM('Red Bull Model'!K99:K102) -> -34.68711 | L13: =SUM('Red Bull Model'!L99:L102) -> -16.428493 | M13: =SUM('Red Bull Model'!M99:M102) -> -15.964293 | N13: =SUM('Red Bull Model'!N99:N102) -> -13.373794 | O13: =SUM('Red Bull Model'!O99:O102) -> -8.7482706 | P13: =SUM('Red Bull Model'!P99:P102) -> -7.1700291
B14: ='Red Bull Model'!B105 -> (Capital expenditure) | I14: ='Red Bull Model'!I105 -> -901.16627 | J14: ='Red Bull Model'!J105 -> -889.7877 | K14: ='Red Bull Model'!K105 -> -958.2798 | L14: ='Red Bull Model'!L105 -> -1029.4333 | M14: ='Red Bull Model'!M105 -> -974.54341 | N14: ='Red Bull Model'!N105 -> -1025.9269 | O14: ='Red Bull Model'!O105 -> -982.48135 | P14: ='Red Bull Model'!P105 -> -1008.0259
B15: Unlevered free cash flow | I15: =SUM(I11:I14) -> 2354.4612 | J15: =SUM(J11:J14) -> 2684.6432 | K15: =SUM(K11:K14) -> 3021.1827 | L15: =SUM(L11:L14) -> 3256.1455 | M15: =SUM(M11:M14) -> 3603.719 | N15: =SUM(N11:N14) -> 3797.5213 | O15: =SUM(O11:O14) -> 4008.2613 | P15: =SUM(P11:P14) -> 4116.0612
A17: Key ratios
B18: Revenue growth | D18: ='Red Bull Model'!D12 -> 0.23914094 | E18: ='Red Bull Model'!E12 -> 0.23908278 | F18: ='Red Bull Model'!F12 -> 0.08981377 | G18: ='Red Bull Model'!G12 -> 0.063768479 | H18: ='Red Bull Model'!H12 -> 0.086309789 | I18: ='Red Bull Model'!I12 -> 0.086622267 | J18: ='Red Bull Model'!J12 -> 0.082925779 | K18: ='Red Bull Model'!K12 -> 0.076975775 | ... P18: ='Red Bull Model'!P12 -> 0.026
B19: EBIT margin | C19: ='Red Bull Model'!C123 -> 0.25719757 | D19: ='Red Bull Model'!D123 -> 0.28954656 | E19: ='Red Bull Model'!E123 -> 0.2366279 | F19: ='Red Bull Model'!F123 -> 0.25905365 | G19: ='Red Bull Model'!G123 -> 0.2612753 | H19: ='Red Bull Model'!H123 -> 0.26392708 | I19: ='Red Bull Model'!I123 -> 0.27324613 | J19: ='Red Bull Model'!J123 -> 0.28232329 | ... P19: ='Red Bull Model'!P123 -> 0.29172347
B20: Cash conversion ratio | I20: =I15/I11 -> 0.87274071 | J20: =J15/J11 -> 0.88938314 | K20: =K15/K11 -> 0.90062649 | L20: =L15/L11 -> 0.89616873 | M20: =M15/M11 -> 0.93170081 | N20: =N15/N11 -> 0.93287434 | O20: =O15/O11 -> 0.95620048 | P20: =P15/P11 -> 0.95819231
B22: Invested capital | G22: ='Red Bull Model'!G84+'Red Bull Model'!G88+'Red Bull Model'!G91-'Red Bull Model'!G74-'Red Bull Model'!G81 -> 3046.2373 | H22: ='Red Bull Model'!H84+'Red Bull Model'!H88+'Red Bull Model'!H91-'Red Bull Model'!H74-'Red Bull Model'!H81 -> 3389.4374 | I22: ='Red Bull Model'!I84+'Red Bull Model'!I88+'Red Bull Model'!I91-'Red Bull Model'!I74-'Red Bull Model'!I81 -> 3732.7548 | J22: ='Red Bull Model'!J84+'Red Bull Model'!J88+'Red Bull Model'!J91-'Red Bull Model'!J74-'Red Bull Model'!J81 -> 4066.6568 | K22: ='Red Bull Model'!K84+'Red Bull Model'!K88+'Red Bull Model'!K91-'Red Bull Model'!K74-'Red Bull Model'!K81 -> 4400.0087 | L22: ='Red Bull Model'!L84+'Red Bull Model'!L88+'Red Bull Model'!L91-'Red Bull Model'!L74-'Red Bull Model'!L81 -> 4777.2699 | M22: ='Red Bull Model'!M84+'Red Bull Model'!M88+'Red Bull Model'!M91-'Red Bull Model'!M74-'Red Bull Model'!M81 -> 5041.4439 | N22: ='Red Bull Model'!N84+'Red Bull Model'!N88+'Red Bull Model'!N91-'Red Bull Model'!N74-'Red Bull Model'!N81 -> 5314.6973 | ... P22: ='Red Bull Model'!P84+'Red Bull Model'!P88+'Red Bull Model'!P91-'Red Bull Model'!P74-'Red Bull Model'!P81 -> 5677.8902
B23: Invested capital growth rate | H23: =H22/G22-1 -> 0.11266364 | I23: =I22/H22-1 -> 0.10129037 | J23: =J22/I22-1 -> 0.089451891 | K23: =K22/J22-1 -> 0.081971973 | L23: =L22/K22-1 -> 0.085741022 | M23: =M22/L22-1 -> 0.055298102 | N23: =N22/M22-1 -> 0.054201424 | O23: =O22/N22-1 -> 0.03454601 | P23: =P22/O22-1 -> 0.032663071
B24: Return on average invested capital | H24: =H11/AVERAGE(G22:H22) -> 0.74523554 | I24: =I11/AVERAGE(H22:I22) -> 0.75756972 | J24: =J11/AVERAGE(I22:J22) -> 0.77404433 | K24: =K11/AVERAGE(J22:K22) -> 0.79240986 | L24: =L11/AVERAGE(K22:L22) -> 0.79182663 | M24: =M11/AVERAGE(L22:M22) -> 0.78786143 | N24: =N11/AVERAGE(M22:N22) -> 0.78615668 | O24: =O11/AVERAGE(N22:O22) -> 0.7753379 | P24: =P11/AVERAGE(O22:P22) -> 0.76871508
B25: Return on new capital invested | H25: =(H11-G11)/(H22-G22) -> 0.61978426 | I25: =(I11-H11)/(I22-H22) -> 0.87304596 | J25: =(J11-I11)/(J22-I22) -> 0.96066094 | K25: =(K11-J11)/(K22-J22) -> 1.0079121 | L25: =(L11-K11)/(L22-K22) -> 0.73920178 | M25: =(M11-L11)/(M22-L22) -> 0.88762035 | N25: =(N11-M11)/(N22-M22) -> 0.74246756 | O25: =(O11-N11)/(O22-N22) -> 0.65951573 | P25: =(P11-O11)/(P22-O22) -> 0.57792141
A27: Terminal value
B28: Long term growth rate | H28: 0.026
B29: WACC | H29: =WACC!D31 -> 0.055612559
B30: Terminal value using long term growth rate | P30: =P15*(1+ltg)/(WACC-ltg) -> 142611.08
B31: Implied terminal EBITDA LTM multiple | P31: =(P30*(1+WACC)^0.5)/P7 -> 22.195123
A33: Discounting
B34: Year | I34: 0.5 | J34: =I34+1 -> 1.5 | K34: =J34+1 -> 2.5 | L34: =K34+1 -> 3.5 | M34: =L34+1 -> 4.5 | N34: =M34+1 -> 5.5 | O34: =N34+1 -> 6.5 | P34: =O34+1 -> 7.5
B35: Discount factor | I35: =1/(1+WACC)^I34 -> 0.97330225 | J35: =1/(1+WACC)^J34 -> 0.92202602 | K35: =1/(1+WACC)^K34 -> 0.87345117 | L35: =1/(1+WACC)^L34 -> 0.82743537 | M35: =1/(1+WACC)^M34 -> 0.78384381 | N35: =1/(1+WACC)^N34 -> 0.74254877 | O35: =1/(1+WACC)^O34 -> 0.70342927 | P35: =1/(1+WACC)^P34 -> 0.66637069
B36: Present value of free cash flows | I36: =I35*I15 -> 2291.6024 | J36: =J35*J15 -> 2475.3109 | K36: =K35*K15 -> 2638.8556 | L36: =L35*L15 -> 2694.25 | M36: =M35*M15 -> 2824.7528 | N36: =N35*N15 -> 2819.8448 | O36: =O35*O15 -> 2819.5283 | P36: =P35*P15 -> 2742.8226
B37: Sum of present value of free cash flows | H37: =SUM(I36:P36) -> 21306.967
B38: Present value of terminal value | H38: =P30*P35 -> 95031.841
B39: Enterprise value | H39: =SUM(H37:H38) -> 116338.81
B41: Cash and other financial assets | H41: ='Red Bull Model'!H74+'Red Bull Model'!H81 -> 2666.7257
B42: Debt and revolver | H42: ='Red Bull Model'!H84+'Red Bull Model'!H88 -> 462.4
B43: Implied equity value | H43: =H39+H41-H42 -> 118543.13
B44: ="Implied "&YEAR(H3)&" EBITDA multiple" -> Implied 2025 EBITDA multiple | H44: =H39/H7 -> 31.310334
B45: ="Implied forward "&YEAR(I3)&" EBITDA multiple" -> Implied forward 2026 EBITDA multiple | H45: =H39/I7 -> 27.868785
B46: ="Implied forward "&YEAR(J3)&" EBITDA multiple" -> Implied forward 2027 EBITDA multiple | H46: =H39/J7 -> 24.942877
A48: Sensitivity
...

Sheet Trading_comps
A1: Trading comparables
C3: Main currency | D3: USD | F3: EUR/USD | G3: 1.1804
C4: Analysis date | D4: 46076 | F4: GBP/USD | G4: 1.3496
C5: Calendarization date | D5: 46022
C7: ="All data in "&D3&"m unless otherwise stated, as of "&TEXT(D4,"dd-mmm-yy") -> All data in USDm unless otherwise stated, as of 23-Feb-26
E8: Share price | F8: Share price | I8: P/E | L8: Revenue | P8: EBITDA | T8: EBIT | X8: EBITDAR | AB8: EBITR | AF8: EV / Revenue | AJ8: EV / EBITDA | AN8: EV / EBIT | AR8: EVR / EBITDAR | AV8: EVR / EBITR | AY8: LTM EBITDA | AZ8: LT EPS | BA8: Post tax | BB8: CY1 Revenue | BC8: CY2 Revenue | BD8: Debt / | BE8: Historical | BF8: Credit | BG8: Total
C9: Company | D9: Share price $ | E9: 52 week high $ | F9: % of high | G9: Market Cap | H9: EV | I9: 2026e | J9: 2027e | K9: LTM | L9: =I9 -> 2026e | M9: =+J9 -> 2027e | O9: LTM | P9: =L9 -> 2026e | Q9: =M9 -> 2027e | S9: LTM | T9: =P9 -> 2026e | U9: =Q9 -> 2027e | W9: LTM | X9: =L9 -> 2026e | Y9: =M9 -> 2027e | AA9: LTM | AB9: =X9 -> 2026e | AC9: =Y9 -> 2027e | AE9: LTM | AF9: =L9 -> 2026e | AG9: =M9 -> 2027e | AI9: LTM | AJ9: =P9 -> 2026e | AK9: =Q9 -> 2027e | AM9: LTM | AN9: =T9 -> 2026e | AO9: =U9 -> 2027e | AQ9: LTM | AR9: =AJ9 -> 2026e | AS9: =AK9 -> 2027e | AU9: LTM | AV9: =AN9 -> 2026e | AW9: =AO9 -> 2027e | AY9: margin | AZ9: growth (%) | BA9: ROIC | BB9: growth | BC9: growth | BD9: LTM EBITDA | BE9: Beta | BF9: Rating | BG9: Debt | BH9: Ticker
A10: Trading comparables longlist
B11: 1 | C11: {=INDIRECT($B11&"!"&C$70)} -> Coca-Cola Company | D11: {=INDIRECT($B11&"!"&D$70)} -> 79.84 | E11: =INDIRECT($B11&"!"&E$70)*INDIRECT($B11&"!"&E$71) -> 80.41 | F11: =D11/E11 -> 0.99291133 | G11: {=INDIRECT($B11&"!"&G$70)} -> 344591.76 | H11: {=INDIRECT($B11&"!"&H$70)} -> 356148.76 | I11: =INDIRECT($B11&"!"&I$70) -> 24.718266 | J11: =INDIRECT($B11&"!"&J$70) -> 23.075145 | K11: =INDIRECT($B11&"!"&K$70) -> 48062 | L11: =INDIRECT($B11&"!"&L$70) -> 49005 | M11: =INDIRECT($B11&"!"&M$70) -> 49824.7 | O11: =INDIRECT($B11&"!"&O$70) -> 16063 | P11: =INDIRECT($B11&"!"&P$70) -> 17272.8 | Q11: =INDIRECT($B11&"!"&Q$70) -> 18252.1 | S11: =INDIRECT($B11&"!"&S$70) -> 15013 | T11: =INDIRECT($B11&"!"&T$70) -> 16172.8 | U11: =INDIRECT($B11&"!"&U$70) -> 17152.1 | W11: =INDIRECT($B11&"!"&W$70) -> 16452 | X11: =INDIRECT($B11&"!"&X$70) -> 17669.432 | Y11: =INDIRECT($B11&"!"&Y$70) -> 18655.367 | AA11: =INDIRECT($B11&"!"&AA$70) -> 15142.537 | AB11: =INDIRECT($B11&"!"&AB$70) -> 16304.879 | AC11: =INDIRECT($B11&"!"&AC$70) -> 17286.388 | AE11: =IFERROR($H11/K11,"N/A ") -> 7.4101944 | AF11: =IFERROR($H11/L11,"N/A ") -> 7.2676005 | AG11: =IFERROR($H11/M11,"N/A ") -> 7.1480363 | AI11: =IFERROR($H11/O11,"N/A ") -> 22.171996 | AJ11: =IFERROR($H11/P11,"N/A ") -> 20.619052 | AK11: =IFERROR($H11/Q11,"N/A ") -> 19.512756 | AM11: =IFERROR($H11/S11,"N/A ") -> 23.722691 | AN11: =IFERROR($H11/T11,"N/A ") -> 22.021466 | AO11: =IFERROR($H11/U11,"N/A ") -> 20.764149 | AQ11: =IFERROR(INDIRECT($B11&"!"&AQ$70)/W11,"N/A ") -> 21.752417 | AR11: =IFERROR(INDIRECT($B11&"!"&AR$70)/X11,"N/A ") -> 20.253665 | AS11: =IFERROR(INDIRECT($B11&"!"&AS$70)/Y11,"N/A ") -> 19.183261 | AU11: =IFERROR(INDIRECT($B11&"!"&AU$70)/AA11,"N/A ") -> 23.633475 | AV11: =IFERROR(INDIRECT($B11&"!"&AV$70)/AB11,"N/A ") -> 21.948692 | AW11: =IFERROR(INDIRECT($B11&"!"&AW$70)/AC11,"N/A ") -> 20.702461 | AY11: =O11/K11 -> 0.33421414 | AZ11: =INDIRECT($B11&"!"&AZ$70) -> 0.065 | BA11: =INDIRECT($B11&"!"&BA$70) -> 0.26677723 | BB11: =+L11/K11-1 -> 0.01962049 | BC11: =+M11/L11-1 -> 0.016726865 | BD11: =INDIRECT("'"&$B11&"'!"&BD$70)/INDIRECT("'"&$B11&"'!"&BD$71) -> 2.8320986 | BE11: =INDIRECT("'"&$B11&"'!"&BE$70) -> 0.57 | BF11: =INDIRECT("'"&$B11&"'!"&BF$70) -> A+ | BG11: =INDIRECT("'"&$B11&"'!"&BG$70) -> 45492 | BH11: =INDIRECT("'"&$B11&"'!"&BH$70) -> KO-US
B12: 2 | C12: {=INDIRECT($B12&"!"&C$70)} -> Keurig Dr Pepper | D12: {=INDIRECT($B12&"!"&D$70)*INDIRECT($B12&"!"&D$71)} -> 29.54 | E12: =INDIRECT($B12&"!"&E$70)*INDIRECT($B12&"!"&E$71) -> 36.12 | F12: =D12/E12 -> 0.81782946 | G12: =INDIRECT($B12&"!"&G$70) -> 40504.205 | H12: =INDIRECT($B12&"!"&H$70) -> 55157.205 | I12: =INDIRECT($B12&"!"&I$70) -> 13.612903 | J12: =INDIRECT($B12&"!"&J$70) -> 12.787879 | K12: =INDIRECT($B12&"!"&K$70) -> 16174 | L12: =INDIRECT($B12&"!"&L$70) -> 17216.2 | M12: =INDIRECT($B12&"!"&M$70) -> 17827 | O12: =INDIRECT($B12&"!"&O$70) -> 4530 | P12: =INDIRECT($B12&"!"&P$70) -> 5066.4 | Q12: =INDIRECT($B12&"!"&Q$70) -> 5298.7 | S12: =INDIRECT($B12&"!"&S$70) -> 3948 | T12: =INDIRECT($B12&"!"&T$70) -> 4466.4 | U12: =INDIRECT($B12&"!"&U$70) -> 4698.7 | W12: =INDIRECT($B12&"!"&W$70) -> 4709 | X12: =INDIRECT($B12&"!"&X$70) -> 5257.0556 | Y12: =INDIRECT($B12&"!"&Y$70) -> 5496.1197 | AA12: =INDIRECT($B12&"!"&AA$70) -> 4007.607 | AB12: =INDIRECT($B12&"!"&AB$70) -> 4529.8883 | AC12: =INDIRECT($B12&"!"&AC$70) -> 4764.4408 | AE12: =IFERROR($H12/K12,"N/A ") -> 3.410239 | AF12: =IFERROR($H12/L12,"N/A ") -> 3.2037967 | AG12: =IFERROR($H12/M12,"N/A ") -> 3.0940262 | AI12: =IFERROR($H12/O12,"N/A ") -> 12.175983 | AJ12: =IFERROR($H12/P12,"N/A ") -> 10.886863 | AK12: =IFERROR($H12/Q12,"N/A ") -> 10.409573 | AM12: =IFERROR($H12/S12,"N/A ") -> 13.970923 | AN12: =IFERROR($H12/T12,"N/A ") -> 12.349365 | AO12: =IFERROR($H12/U12,"N/A ") -> 11.738822 | AQ12: =IFERROR(INDIRECT($B12&"!"&AQ$70)/W12,"N/A ") -> 11.908092 | AR12: =IFERROR(INDIRECT($B12&"!"&AR$70)/X12,"N/A ") -> 10.666656 | AS12: =IFERROR(INDIRECT($B12&"!"&AS$70)/Y12,"N/A ") -> 10.20269 | AU12: =IFERROR(INDIRECT($B12&"!"&AU$70)/AA12,"N/A ") -> 13.992192 | AV12: =IFERROR(INDIRECT($B12&"!"&AV$70)/AB12,"N/A ") -> 12.378938 | AW12: =IFERROR(INDIRECT($B12&"!"&AW$70)/AC12,"N/A ") -> 11.769525 | AY12: =O12/K12 -> 0.28007914 | AZ12: =INDIRECT($B12&"!"&AZ$70) -> 0.065 | BA12: =INDIRECT($B12&"!"&BA$70) -> 0.075943968 | BB12: =+L12/K12-1 -> 0.06443675 | BC12: =+M12/L12-1 -> 0.035478212 | BD12: =INDIRECT("'"&$B12&"'!"&BD$70)/INDIRECT("'"&$B12&"'!"&BD$71) -> 3.7172185 | BE12: =INDIRECT("'"&$B12&"'!"&BE$70) -> 0.55 | BF12: =INDIRECT("'"&$B12&"'!"&BF$70) -> BBB | BG12: =INDIRECT("'"&$B12&"'!"&BG$70) -> 16839 | BH12: =INDIRECT("'"&$B12&"'!"&BH$70) -> KDP-US
B13: 3 | C13: {=INDIRECT($B13&"!"&C$70)} -> Monster Beverage | D13: {=INDIRECT($B13&"!"&D$70)} -> 83.76 | E13: =INDIRECT($B13&"!"&E$70)*INDIRECT($B13&"!"&E$71) -> 83.98 | F13: =D13/E13 -> 0.99738033 | G13: {=INDIRECT($B13&"!"&G$70)} -> 83024.655 | H13: {=INDIRECT($B13&"!"&H$70)} -> 80086.151 | I13: =INDIRECT($B13&"!"&I$70) -> 37.061947 | J13: =INDIRECT($B13&"!"&J$70) -> 32.847059 | K13: =INDIRECT($B13&"!"&K$70) -> 7975.331 | L13: =INDIRECT($B13&"!"&L$70) -> 9006.9 | M13: =INDIRECT($B13&"!"&M$70) -> 9819.6 | O13: =INDIRECT($B13&"!"&O$70) -> 2552.979 | P13: =INDIRECT($B13&"!"&P$70) -> 2914.6 | Q13: =INDIRECT($B13&"!"&Q$70) -> 3212.8 | S13: =INDIRECT($B13&"!"&S$70) -> 2450.344 | T13: =INDIRECT($B13&"!"&T$70) -> 2834.6 | U13: =INDIRECT($B13&"!"&U$70) -> 3132.8 | W13: =INDIRECT($B13&"!"&W$70) -> 2568.775 | X13: =INDIRECT($B13&"!"&X$70) -> 2933.5882 | Y13: =INDIRECT($B13&"!"&Y$70) -> 3233.5015 | AA13: =INDIRECT($B13&"!"&AA$70) -> 2455.6041 | AB13: =INDIRECT($B13&"!"&AB$70) -> 2840.9231 | AC13: =INDIRECT($B13&"!"&AC$70) -> 3139.6936 | AE13: =IFERROR($H13/K13,"N/A ") -> 10.041734 | AF13: =IFERROR($H13/L13,"N/A ") -> 8.8916443 | AG13: =IFERROR($H13/M13,"N/A ") -> 8.1557447 | AI13: =IFERROR($H13/O13,"N/A ") -> 31.369686 | AJ13: =IFERROR($H13/P13,"N/A ") -> 27.477579 | AK13: =IFERROR($H13/Q13,"N/A ") -> 24.927213 | AM13: =IFERROR($H13/S13,"N/A ") -> 32.683636 | AN13: =IFERROR($H13/T13,"N/A ") -> 28.253069 | AO13: =IFERROR($H13/U13,"N/A ") -> 25.563761 | AQ13: =IFERROR(INDIRECT($B13&"!"&AQ$70)/W13,"N/A ") -> 31.198738 | AR13: =IFERROR(INDIRECT($B13&"!"&AR$70)/X13,"N/A ") -> 27.318946 | AS13: =IFERROR(INDIRECT($B13&"!"&AS$70)/Y13,"N/A ") -> 24.785063 | AU13: =IFERROR(INDIRECT($B13&"!"&AU$70)/AA13,"N/A ") -> 32.636588 | AV13: =IFERROR(INDIRECT($B13&"!"&AV$70)/AB13,"N/A ") -> 28.210034 | AW13: =IFERROR(INDIRECT($B13&"!"&AW$70)/AC13,"N/A ") -> 25.525592 | AY13: =O13/K13 -> 0.32010947 | AZ13: =INDIRECT($B13&"!"&AZ$70) -> 0.125 | BA13: =INDIRECT($B13&"!"&BA$70) -> 0.40274074 | BB13: =+L13/K13-1 -> 0.12934498 | BC13: =+M13/L13-1 -> 0.090230823 | BD13: =INDIRECT("'"&$B13&"'!"&BD$70)/INDIRECT("'"&$B13&"'!"&BD$71) -> 0 | BE13: =INDIRECT("'"&$B13&"'!"&BE$70) -> 0.63 | BF13: =INDIRECT("'"&$B13&"'!"&BF$70) -> N/A | BG13: =INDIRECT("'"&$B13&"'!"&BG$70) -> 0 | BH13: =INDIRECT("'"&$B13&"'!"&BH$70) -> MNST-US
B14: 4 | C14: PepsiCo | D14: 164.94 | E14: 171.48 | F14: =D14/E14 -> 0.96186144 | G14: 226465.5 | H14: 262775.5 | I14: 19.1 | J14: =D14/9.2 -> 17.928261 | K14: 93925 | L14: 98553.2 | M14: 101645.2 | O14: 18363 | P14: 19494.6 | Q14: 20515.6 | S14: =O14-3451 -> 14912 | T14: =P14-3451 -> 16043.6 | U14: =Q14-3451 -> 17064.6 | AE14: =IFERROR($H14/K14,"N/A ") -> 2.7977163 | AF14: =IFERROR($H14/L14,"N/A ") -> 2.6663315 | AG14: =IFERROR($H14/M14,"N/A ") -> 2.5852229 | AI14: =IFERROR($H14/O14,"N/A ") -> 14.310053 | AJ14: =IFERROR($H14/P14,"N/A ") -> 13.479399 | AK14: =IFERROR($H14/Q14,"N/A ") -> 12.80857 | AM14: =IFERROR($H14/S14,"N/A ") -> 17.621748 | AN14: =IFERROR($H14/T14,"N/A ") -> 16.378836 | AO14: =IFERROR($H14/U14,"N/A ") -> 15.398867 | AY14: =O14/K14 -> 0.19550705 | AZ14: 0.078 | BA14: 0.14 | BB14: =+L14/K14-1 -> 0.049275486 | BC14: =+M14/L14-1 -> 0.031373918 | BD14: =BG14/O14 -> 2.6783205 | BE14: 0.6 | BF14: A+ | BG14: 49182 | BH14: PEP-US
B15: 5 | C15: Danone | D15: =73.6*G3 -> 86.87744 | E15: =80.14*G3 -> 94.597256 | F15: =D15/E15 -> 0.91839281 | G15: =47110*G3 -> 55608.644 | H15: =55640*G3 -> 65677.456 | I15: 18.36 | J15: =D15/(4.34*G3) -> 16.958525 | K15: 32204.853 | L15: 33183.877 | M15: 34531.894 | O15: 5542.5682 | P15: 5872.608 | Q15: 6176.0889 | S15: =O15-1168 -> 4374.5682 | T15: =P15-1168 -> 4704.608 | U15: =Q15-1168 -> 5008.0889 | AE15: =IFERROR($H15/K15,"N/A ") -> 2.0393652 | AF15: =IFERROR($H15/L15,"N/A ") -> 1.9791978 | AG15: =IFERROR($H15/M15,"N/A ") -> 1.9019361 | AI15: =IFERROR($H15/O15,"N/A ") -> 11.849643 | AJ15: =IFERROR($H15/P15,"N/A ") -> 11.183695 | AK15: =IFERROR($H15/Q15,"N/A ") -> 10.63415 | AM15: =IFERROR($H15/S15,"N/A ") -> 15.013472 | AN15: =IFERROR($H15/T15,"N/A ") -> 13.96024 | AO15: =IFERROR($H15/U15,"N/A ") -> 13.114275 | AY15: =O15/K15 -> 0.17210351 | AZ15: 0.05 | BA15: 0.055 | BB15: =+L15/K15-1 -> 0.030399883 | BC15: =+M15/L15-1 -> 0.040622643 | BD15: =BG15/O15 -> 2.8147601 | BE15: 0.5 | BF15: BBB+ | BG15: =10447+5154 -> 15601 | BH15: BN-FR
B16: 6 | C16: National Beverage | D16: 37.01 | E16: 47.89 | F16: =D16/E16 -> 0.7728127 | G16: 3467.8 | H16: 3198.7 | I16: 18.1 | J16: =D16/2.06 -> 17.966019 | K16: 1119.5 | L16: 1198.4 | M16: 1209.3 | O16: 260.2 | P16: 257.7 | Q16: 257.1 | S16: =O16-20.801 -> 239.399 | T16: =P16-20.801 -> 236.899 | U16: =Q16-20.801 -> 236.299 | AE16: =IFERROR($H16/K16,"N/A ") -> 2.8572577 | AF16: =IFERROR($H16/L16,"N/A ") -> 2.6691422 | AG16: =IFERROR($H16/M16,"N/A ") -> 2.6450839 | AI16: =IFERROR($H16/O16,"N/A ") -> 12.293236 | AJ16: =IFERROR($H16/P16,"N/A ") -> 12.412495 | AK16: =IFERROR($H16/Q16,"N/A ") -> 12.441462 | AM16: =IFERROR($H16/S16,"N/A ") -> 13.361376 | AN16: =IFERROR($H16/T16,"N/A ") -> 13.502379 | AO16: =IFERROR($H16/U16,"N/A ") -> 13.536663 | AY16: =O16/K16 -> 0.23242519 | AZ16: N/A | BA16: 0.39888127 | BB16: =+L16/K16-1 -> 0.070477892 | BC16: =+M16/L16-1 -> 0.0090954606 | BD16: =BG16/O16 -> 0 | BE16: 0.588622 | BF16: N/A | BG16: 0 | BH16: FIZZ-US
B17: 7 | C17: Fevertree Drinks | D17: =9.48*G4 -> 12.794208 | E17: =10.2*G4 -> 13.76592 | F17: =D17/E17 -> 0.92941176 | G17: 1350 | H17: 1180 | I17: =D17/(0.28*G4) -> 33.857143 | J17: =D17/(0.37*G4) -> 25.621622 | K17: =375.3*G4 -> 506.50488 | L17: =395.6*G4 -> 533.90176 | M17: =436.7*G4 -> 589.37032 | O17: 59.78728 | P17: 67.48 | Q17: 86.91424 | S17: =O17-6.5-3.1 -> 50.18728 | T17: =P17-6.5-3.1 -> 57.88 | U17: =Q17-6.5-3.1 -> 77.31424 | AE17: =IFERROR($H17/K17,"N/A ") -> 2.3296913 | AF17: =IFERROR($H17/L17,"N/A ") -> 2.2101444 | AG17: =IFERROR($H17/M17,"N/A ") -> 2.0021368 | AI17: =IFERROR($H17/O17,"N/A ") -> 19.73664 | AJ17: =IFERROR($H17/P17,"N/A ") -> 17.486663 | AK17: =IFERROR($H17/Q17,"N/A ") -> 13.576601 | AM17: =IFERROR($H17/S17,"N/A ") -> 23.511934 | AN17: =IFERROR($H17/T17,"N/A ") -> 20.387008 | AO17: =IFERROR($H17/U17,"N/A ") -> 15.262389 | AY17: =O17/K17 -> 0.1180389 | AZ17: 0.152 | BA17: 0.04969722 | BB17: =+L17/K17-1 -> 0.054090061 | BC17: =+M17/L17-1 -> 0.10389282 | BD17: =BG17/O17 -> 0 | BE17: 1.100264 | BF17: N/A | BG17: 0 | BH17: FEVR-GB
B18: 8 | C18: Celsius | D18: 48.32 | E18: 66.74 | F18: =D18/E18 -> 0.7240036 | G18: 12662.3 | H18: 13579.5 | I18: =D18/1.5 -> 32.213333 | J18: =D18/1.83 -> 26.404372 | K18: 2125.9 | L18: 2443.1 | M18: 3227.7 | O18: 547.9 | P18: 601.5 | Q18: 736.1 | S18: =O18-7.274 -> 540.626 | T18: =P18-7.274 -> 594.226 | U18: =Q18-7.274 -> 728.826 | AE18: =IFERROR($H18/K18,"N/A ") -> 6.3876476 | AF18: =IFERROR($H18/L18,"N/A ") -> 5.5583071 | AG18: =IFERROR($H18/M18,"N/A ") -> 4.2071754 | AI18: =IFERROR($H18/O18,"N/A ") -> 24.784632 | AJ18: =IFERROR($H18/P18,"N/A ") -> 22.57606 | AK18: =IFERROR($H18/Q18,"N/A ") -> 18.447901 | AM18: =IFERROR($H18/S18,"N/A ") -> 25.118104 | AN18: =IFERROR($H18/T18,"N/A ") -> 22.852416 | AO18: =IFERROR($H18/U18,"N/A ") -> 18.632019 | AY18: =O18/K18 -> 0.25772614 | AZ18: 0.2 | BA18: 0.232 | BB18: =+L18/K18-1 -> 0.14920739 | BC18: =+M18/L18-1 -> 0.32114936 | BD18: =BG18/O18 -> 3.144917 | BE18: 1.57426 | BF18: N/A | BG18: 1723.1 | BH18: CELH-US
C20: Median | AY20: =MEDIAN(AY11:AY18) -> 0.24507566 | BB20: =MEDIAN(BB11:BB18) -> 0.059263406 | BC20: =MEDIAN(BC11:BC18) -> 0.038050428
C21: Average | AY21: =AVERAGE((AY11:AY18)) -> 0.23877544 | BB21: =AVERAGE((BB11:BB18)) -> 0.070856617 | BC21: =AVERAGE((BC11:BC18)) -> 0.081071263
C23: Red Bull | K23: ='Red Bull Model'!F54 -> 10553.988 | L23: ='Red Bull Model'!G54 -> 11227 | M23: ='Red Bull Model'!H54 -> 12196 | O23: ='Red Bull Model'!F60 -> 3134.0492 | P23: ='Red Bull Model'!G60 -> 3375.5418 | Q23: ='Red Bull Model'!H60 -> 3715.6681 | S23: ='Red Bull Model'!F63 -> 2734.0492 | T23: ='Red Bull Model'!G63 -> 2933.3378 | U23: ='Red Bull Model'!H63 -> 3218.8547 | AY23: ='Red Bull Model'!F60/'Red Bull Model'!F54 -> 0.29695402 | BB23: ='Red Bull Model'!G12 -> 0.063768479 | BC23: ='Red Bull Model'!H12 -> 0.086309789
I25: P/E | AF25: EV / Revenue | AJ25: EV / EBITDA | AN25: EV / EBIT | AR25: EVR / EBITDAR | AV25: EVR / EBITR | AY25: LTM EBITDA / | AZ25: LT EPS
C26: Company | I26: =+AN9 -> 2026e | J26: =+AO9 -> 2027e | AE26: =AE9 -> LTM | AF26: =AF9 -> 2026e | AG26: =AG9 -> 2027e | AI26: =AI9 -> LTM | AJ26: =AJ9 -> 2026e | AK26: =AK9 -> 2027e | AM26: =AM9 -> LTM | AN26: =AN9 -> 2026e | AO26: =AO9 -> 2027e | AQ26: =AQ9 -> LTM | AR26: =AR9 -> 2026e | AS26: =AS9 -> 2027e | AU26: =AU9 -> LTM | AV26: =AV9 -> 2026e | AW26: =AW9 -> 2027e | AY26: Revenue | AZ26: growth (%)
A27: Trading comparables shortlist
B28: =B11 -> 1 | C28: =OFFSET(C$10,$B28,0) -> Coca-Cola Company | I28: =OFFSET(I$10,$B28,0) -> 24.718266 | J28: =OFFSET(J$10,$B28,0) -> 23.075145 | AE28: =OFFSET(AE$10,$B28,0) -> 7.4101944 | AF28: =OFFSET(AF$10,$B28,0) -> 7.2676005 | AG28: =OFFSET(AG$10,$B28,0) -> 7.1480363 | AI28: =OFFSET(AI$10,$B28,0) -> 22.171996 | AJ28: =OFFSET(AJ$10,$B28,0) -> 20.619052 | AK28: =OFFSET(AK$10,$B28,0) -> 19.512756 | AM28: =OFFSET(AM$10,$B28,0) -> 23.722691 | AN28: =OFFSET(AN$10,$B28,0) -> 22.021466 | AO28: =OFFSET(AO$10,$B28,0) -> 20.764149 | AQ28: =AQ11 -> 21.752417 | AR28: =AR11 -> 20.253665 | AS28: =AS11 -> 19.183261 | AU28: =AU11 -> 23.633475 | AV28: =AV11 -> 21.948692 | AW28: =AW11 -> 20.702461 | AY28: =OFFSET(AY$10,$B28,0) -> 0.33421414 | AZ28: =OFFSET(AZ$10,$B28,0) -> 0.065
B29: 3 | C29: =OFFSET(C$10,$B29,0) -> Monster Beverage | I29: =OFFSET(I$10,$B29,0) -> 37.061947 | J29: =OFFSET(J$10,$B29,0) -> 32.847059 | AE29: =OFFSET(AE$10,$B29,0) -> 10.041734 | AF29: =OFFSET(AF$10,$B29,0) -> 8.8916443 | AG29: =OFFSET(AG$10,$B29,0) -> 8.1557447 | AI29: =OFFSET(AI$10,$B29,0) -> 31.369686 | AJ29: =OFFSET(AJ$10,$B29,0) -> 27.477579 | AK29: =OFFSET(AK$10,$B29,0) -> 24.927213 | AM29: =OFFSET(AM$10,$B29,0) -> 32.683636 | AN29: =OFFSET(AN$10,$B29,0) -> 28.253069 | AO29: =OFFSET(AO$10,$B29,0) -> 25.563761 | AY29: =OFFSET(AY$10,$B29,0) -> 0.32010947 | AZ29: =OFFSET(AZ$10,$B29,0) -> 0.125
B30: 4 | C30: =OFFSET(C$10,$B30,0) -> PepsiCo | I30: =OFFSET(I$10,$B30,0) -> 19.1 | J30: =OFFSET(J$10,$B30,0) -> 17.928261 | AE30: =OFFSET(AE$10,$B30,0) -> 2.7977163 | AF30: =OFFSET(AF$10,$B30,0) -> 2.6663315 | AG30: =OFFSET(AG$10,$B30,0) -> 2.5852229 | AI30: =OFFSET(AI$10,$B30,0) -> 14.310053 | AJ30: =OFFSET(AJ$10,$B30,0) -> 13.479399 | AK30: =OFFSET(AK$10,$B30,0) -> 12.80857 | AM30: =OFFSET(AM$10,$B30,0) -> 17.621748 | AN30: =OFFSET(AN$10,$B30,0) -> 16.378836 | AO30: =OFFSET(AO$10,$B30,0) -> 15.398867 | AY30: =OFFSET(AY$10,$B30,0) -> 0.19550705 | AZ30: =OFFSET(AZ$10,$B30,0) -> 0.078
C32: Median | J32: =MEDIAN(J28:J30) -> 23.075145 | AK32: =MEDIAN(AK28:AK30) -> 19.512756
C34: Red Bull 2027 net income | J34: ='Red Bull Model'!H71 -> 2412.7158
C35: Implied equity value | J35: =J34*J32 -> 55673.767
C37: Red Bull 2027 EBITDA | AK37: ='Red Bull Model'!J60 -> 4664.2097
C38: Implied enterprise value | AK38: =AK37*AK32 -> 91011.584
C39: Net debt/(cash) | AK39: ='Red Bull Model'!J136 -> -1766.0417
C40: Implied equity value | AK40: =AK38-AK39 -> 92777.625
A42: End
A69: DO NOT DELETE
C70: COMPANY_NAME | D70: COMP_SHAREPRICE | E70: SHAREPRICE_HIGH | G70: COMP_EQ_VALUE | H70: COMP_EV | I70: PE_CY1 | J70: PE_CY2 | K70: SALES_LTM | L70: SALES_CY1 | M70: SALES_CY2 | O70: EBITDA_LTM | P70: EBITDA_CY1 | Q70: EBITDA_CY2 | S70: EBIT_LTM | T70: EBIT_CY1 | U70: EBIT_CY2 | W70: EBITDAR_LTM | X70: EBITDAR_CY1 | Y70: EBITDAR_CY2 | AA70: EBITR_LTM | AB70: EBITR_CY1 | AC70: EBITR_CY2 | AQ70: EVR | AR70: EVR | AS70: EVR | AU70: EVR | AV70: EVR | AW70: EVR | AZ70: EPS_5YR_GROWTH | BA70: ROIC | BD70: TOTAL_DEBT | BE70: BETA | BF70: CREDIT_RATING | BG70: TOTAL_DEBT | BH70: Ticker
D71: COMP_FX | E71: COMP_FX | G71: PE_CY1 | H71: PE_CY2 | BD71: EBITDA_LTM

Sheet 1
A1: Coca-Cola Company
E2: Analyst name | G2: Amgad Bashir
A4: Key data | E4: Enterprise value summary
B5: Ticker | C5: KO-US | E5: ="Enterprise value calculation in "&MAIN_CURRENCY&" MM" -> Enterprise value calculation in USD MM
B6: Country | C6: United States | E6: + Diluted equity value | H6: =D36*'1'!COMP_FX -> 344591.76
B7: Analysis date | C7: =ANALYSIS_DATE -> 46076 | E7: + Debt | H7: =SUM(G31:G33)*'1'!COMP_FX -> 45492
B8: Calendarize to | C8: =Trading_comps!D5 -> 46022 | E8: - Cash and ST investments | H8: =SUM(J31:J32)*'1'!COMP_FX -> 15806
B9: Currency / FX | C9: =MAIN_CURRENCY -> USD | E9: - Other adjustments | H9: =(SUM(J33:J37)-SUM(G34:G37))*'1'!COMP_FX -> 18129
B10: Marginal tax rate | C10: 0.223 | E10: = Enterprise value | H10: ='1'!COMP_EQ_VALUE+'1'!TOTAL_DEBT-H8-H9 -> 356148.76
B11: Historical year end | C11: 46022
B12: Last filing date US format | C12: 12/31/2025 | E12: Calendarized key numbers
B13: Last filing date Intl format | C13: =DATE(RIGHT(C12,4),LEFT(C12,2),MID(C12,4,2)) -> 46022 | E13: ="Numbers in "&MAIN_CURRENCY&" MM" -> Numbers in USD MM | G13: LTM | H13: =YEAR($C$8)+1&"e" -> 2026e | I13: =YEAR($C$8)+2&"e" -> 2027e | J13: =YEAR($C$8)+3&"e" -> 2028e | K13: =YEAR($C$8)+4&"e" -> 2029e
B14: Home currency | C14: USD | E14: Revenue | G14: =G44*'1'!COMP_FX -> 48062 | H14: =IF(I$80>0,SUMPRODUCT('1'!COMP_CALENDARIZE_PERCENTAGES,H44:J44)*I$81*'1'!COMP_FX,"N/A") -> 49005 | I14: =IF(J$80>0,SUMPRODUCT('1'!COMP_CALENDARIZE_PERCENTAGES,I44:K44)*J$81*'1'!COMP_FX,"N/A") -> 49824.7 | J14: =IF(K$80>0,SUMPRODUCT('1'!COMP_CALENDARIZE_PERCENTAGES,J44:L44)*K$81*'1'!COMP_FX,"N/A") -> 52528.6 | K14: =IF(L$80>0,SUMPRODUCT('1'!COMP_CALENDARIZE_PERCENTAGES,K44:M44)*L$81*'1'!COMP_FX,"N/A") -> N/A
B15: FX rate | C15: 1 | E15: EBITDA | G15: =G55*'1'!COMP_FX -> 16063 | H15: =IF(I$80>0,SUMPRODUCT('1'!COMP_CALENDARIZE_PERCENTAGES,H55:J55)*I$81*'1'!COMP_FX,"N/A") -> 17272.8 | I15: =IF(J$80>0,SUMPRODUCT('1'!COMP_CALENDARIZE_PERCENTAGES,I55:K55)*J$81*'1'!COMP_FX,"N/A") -> 18252.1 | J15: =IF(K$80>0,SUMPRODUCT('1'!COMP_CALENDARIZE_PERCENTAGES,J55:L55)*K$81*'1'!COMP_FX,"N/A") -> 19728.3 | K15: =IF(L$80>0,SUMPRODUCT('1'!COMP_CALENDARIZE_PERCENTAGES,K55:M55)*L$81*'1'!COMP_FX,"N/A") -> N/A
B16: Last closing price | C16: 79.84 | E16: EBIT | G16: =G53*'1'!COMP_FX -> 15013 | H16: =IF(I$80>0,SUMPRODUCT('1'!COMP_CALENDARIZE_PERCENTAGES,H53:J53)*I$81*'1'!COMP_FX,"N/A") -> 16172.8 | I16: =IF(J$80>0,SUMPRODUCT('1'!COMP_CALENDARIZE_PERCENTAGES,I53:K53)*J$81*'1'!COMP_FX,"N/A") -> 17152.1 | J16: =IF(K$80>0,SUMPRODUCT('1'!COMP_CALENDARIZE_PERCENTAGES,J53:L53)*K$81*'1'!COMP_FX,"N/A") -> 18628.3 | K16: =IF(L$80>0,SUMPRODUCT('1'!COMP_CALENDARIZE_PERCENTAGES,K53:M53)*L$81*'1'!COMP_FX,"N/A") -> N/A
B17: 52 week low | C17: 65.35 | E17: EPS | H17: =IF(I$80>0,SUMPRODUCT('1'!COMP_CALENDARIZE_PERCENTAGES,H56:J56)*I$81*'1'!COMP_FX,"N/A") -> 3.23 | I17: =IF(J$80>0,SUMPRODUCT('1'!COMP_CALENDARIZE_PERCENTAGES,I56:K56)*J$81*'1'!COMP_FX,"N/A") -> 3.46 | J17: =IF(K$80>0,SUMPRODUCT('1'!COMP_CALENDARIZE_PERCENTAGES,J56:L56)*K$81*'1'!COMP_FX,"N/A") -> 3.7 | K17: =IF(L$80>0,SUMPRODUCT('1'!COMP_CALENDARIZE_PERCENTAGES,K56:M56)*L$81*'1'!COMP_FX,"N/A") -> N/A
B18: 52 week high | C18: 80.41
B19: Credit rating | C19: A+ | E19: Calendarized multiples to December 31
B20: Beta | C20: 0.57 | G20: =G13 -> LTM | H20: =H13 -> 2026e | I20: =I13 -> 2027e | J20: =J13 -> 2028e | K20: =K13 -> 2029e
B21: 5 year EPS forward growth | C21: 0.065 | E21: EV / Revenue | G21: =IF(G14<>0,$H$10/G14,"N/A") -> 7.4101944 | H21: =IF(ISNUMBER(H14),$H$10/H14,"N/A") -> 7.2676005 | I21: =IF(ISNUMBER(I14),$H$10/I14,"N/A") -> 7.1480363 | J21: =IF(ISNUMBER(J14),$H$10/J14,"N/A") -> 6.7800925 | K21: =IFERROR($H$10/K14,"N/A") -> N/A
B22: LTM EBIT margin | C22: =G53/G44 -> 0.31236736 | E22: EV / EBITDA | G22: =IF(G15<>0,$H$10/G15,"N/A") -> 22.171996 | H22: =IF(ISNUMBER(H15),$H$10/H15,"N/A") -> 20.619052 | I22: =IF(ISNUMBER(I15),$H$10/I15,"N/A") -> 19.512756 | J22: =IF(ISNUMBER(J15),$H$10/J15,"N/A") -> 18.052684 | K22: =IFERROR($H$10/K15,"N/A") -> N/A
B23: Return on invested capital | C23: =G53*(1-'1'!COMP_MTR)/D39 -> 0.26677723 | E23: EV / EBIT | G23: =IF(G16<>0,$H$10/G16,"N/A") -> 23.722691 | H23: =IF(ISNUMBER(H16),$H$10/H16,"N/A") -> 22.021466 | I23: =IF(ISNUMBER(I16),$H$10/I16,"N/A") -> 20.764149 | J23: =IF(ISNUMBER(J16),$H$10/J16,"N/A") -> 19.118694 | K23: =IFERROR($H$10/K16,"N/A") -> N/A
E24: PE | H24: =IF(ISNUMBER(H17),($C$16*'1'!COMP_FX)/H17,"N/A") -> 24.718266 | I24: =IF(ISNUMBER(I17),($C$16*'1'!COMP_FX)/I17,"N/A") -> 23.075145 | J24: =IF(ISNUMBER(J17),($C$16*'1'!COMP_FX)/J17,"N/A") -> 21.578378 | K24: =IFERROR(($C$16*'1'!COMP_FX)/K17,"N/A") -> N/A
E25: P / BV | G25: =D36/D37 -> 10.71192
E26: Total debt / LTM EBITDA | G26: =IF(G15=0,"N/A",H7/G15) -> 2.8320986
A28: Enterprise value calculation (home currency) | M28: Share options and RSUs
M29: Tranche | N29: Number | O29: Strike | P29: New shares
B30: Equity valuation | E30: Financial liabilities calculation | H30: Financial assets calculation | M30: Options | N30: 27 | O30: 55.74 | P30: =MAX(('1'!COMP_SHAREPRICE-O30)/'1'!COMP_SHAREPRICE*N30,0) -> 8.1500501
B31: Shares outstanding as of | D31: 46071 | E31: Debt - short term | G31: 1551 | H31: Cash and ST investments | J31: =10270+3602 -> 13872 | M31: Performance share units | N31: 2.62 | O31: 0 | P31: =MAX(('1'!COMP_SHAREPRICE-O31)/'1'!COMP_SHAREPRICE*N31,0) -> 2.62
B32: Basic shares outstanding | D32: 4300.7231 | E32: Debt - current maturities | G32: 1822 | H32: Marketable securities | J32: 1934 | M32: Time based RSUs | N32: 4.536 | O32: 0 | P32: =MAX(('1'!COMP_SHAREPRICE-O32)/'1'!COMP_SHAREPRICE*N32,0) -> 4.536
B33: Other adjustments | D33: 0 | E33: Debt - long term | G33: 42119 | H33: Equity method investments | J33: 20235 | M33: Tranche 4 | N33: 0 | O33: 0 | P33: =MAX(('1'!COMP_SHAREPRICE-O33)/'1'!COMP_SHAREPRICE*N33,0) -> 0
B34: Dilution from share options | D34: =P38 -> 15.30605 | E34: Preferred equity | G34: 0 | H34: Other investments | J34: 0 | M34: Tranche 5 | N34: 0 | O34: 0 | P34: =MAX(('1'!COMP_SHAREPRICE-O34)/'1'!COMP_SHAREPRICE*N34,0) -> 0
B35: Diluted shares outstanding | D35: =SUM(D32:D34) -> 4316.0291 | E35: NCI | G35: 2106 | H35: Other | J35: 0 | M35: Tranche 6 | N35: 0 | O35: 0 | P35: =MAX(('1'!COMP_SHAREPRICE-O35)/'1'!COMP_SHAREPRICE*N35,0) -> 0
B36: Diluted equity value | D36: =D35*'1'!COMP_SHAREPRICE -> 344591.76 | E36: Other | G36: 0 | H36: Other | J36: 0 | M36: Tranche 7 | N36: 0 | O36: 0 | P36: =MAX(('1'!COMP_SHAREPRICE-O36)/'1'!COMP_SHAREPRICE*N36,0) -> 0
B37: Shareholders' equity | D37: 32169 | E37: Other | G37: 0 | H37: Other | J37: 0 | M37: Tranche 8 | N37: 0 | O37: 0 | P37: =MAX(('1'!COMP_SHAREPRICE-O37)/'1'!COMP_SHAREPRICE*N37,0) -> 0
B38: Net debt and other adjustments | D38: =G39-J39 -> 11557 | M38: Total | P38: =SUM(P30:P37) -> 15.30605
B39: Invested capital | D39: =D37+D38 -> 43726 | E39: Total financial liabilities | G39: =SUM(G31:G37) -> 47598 | H39: Total financial assets | J39: =SUM(J31:J37) -> 36041
A41: Earnings (home currency) | I41: Consensus estimates
C42: Annual | D42: Old 10-Q/Interim | E42: New 10-Q/interim | F42: Other adjustments | G42: Adj. LTM | H42: Fiscal Year | I42: FY +1 | J42: FY +2 | K42: FY +3 | L42: FY +4
B43: Date | C43: =C11 -> 46022 | D43: 0 | E43: 0 | G43: =C13 -> 46022 | H43: =C43 -> 46022 | I43: =EDATE(C43,12) -> 46387 | J43: =EDATE(I43,12) -> 46752 | K43: =EDATE(J43,12) -> 47118 | L43: =EDATE(K43,12) -> 47483
...

Sheet 2
A1: Keurig Dr Pepper
E2: Analyst name | G2: Amgad Bashir
A4: Key data | E4: Enterprise value summary
B5: Ticker | C5: KDP-US | E5: ="Enterprise value calculation in "&MAIN_CURRENCY&" MM" -> Enterprise value calculation in USD MM
B6: Country | C6: United States | E6: + Diluted equity value | H6: =D36*'2'!COMP_FX -> 40504.205
B7: Analysis date | C7: =ANALYSIS_DATE -> 46076 | E7: + Debt | H7: =SUM(G31:G36)*'2'!COMP_FX -> 16839
B8: Calendarize to | C8: =Trading_comps!D5 -> 46022 | E8: - Cash and ST investments | H8: =SUM(J31:J32)*'2'!COMP_FX -> 569
B9: Currency / FX | C9: =MAIN_CURRENCY -> USD | E9: - Other adjustments | H9: =(SUM(J33:J37)-SUM(G37))*'2'!COMP_FX -> 1617
B10: Marginal tax rate | C10: 0.231 | E10: = Enterprise value | H10: ='2'!COMP_EQ_VALUE+'2'!TOTAL_DEBT-H8-H9 -> 55157.205
B11: Historical year end | C11: 45657
B12: Last filing date US format | C12: 09/30/2025 | E12: Calendarized key numbers
B13: Last filing date Intl format | C13: =DATE(RIGHT(C12,4),LEFT(C12,2),MID(C12,4,2)) -> 45930 | E13: ="Numbers in "&MAIN_CURRENCY&" MM" -> Numbers in USD MM | G13: LTM | H13: =YEAR($C$8)+1&"e" -> 2026e | I13: =YEAR($C$8)+2&"e" -> 2027e | J13: =YEAR($C$8)+3&"e" -> 2028e | K13: =YEAR($C$8)+4&"e" -> 2029e
B14: Home currency | C14: USD | E14: Revenue | G14: =G44*'2'!COMP_FX -> 16174 | H14: =IF(I$80>0,SUMPRODUCT('2'!COMP_CALENDARIZE_PERCENTAGES,H44:J44)*I$81*'2'!COMP_FX,"N/A") -> 17216.2 | I14: =IF(J$80>0,SUMPRODUCT('2'!COMP_CALENDARIZE_PERCENTAGES,I44:K44)*J$81*'2'!COMP_FX,"N/A") -> 17827 | J14: =IF(K$80>0,SUMPRODUCT('2'!COMP_CALENDARIZE_PERCENTAGES,J44:L44)*K$81*'2'!COMP_FX,"N/A") -> N/A | K14: =IF(L$80>0,SUMPRODUCT('2'!COMP_CALENDARIZE_PERCENTAGES,K44:M44)*L$81*'2'!COMP_FX,"N/A") -> N/A
B15: FX rate | C15: 1 | E15: EBITDA | G15: =G55*'2'!COMP_FX -> 4530 | H15: =IF(I$80>0,SUMPRODUCT('2'!COMP_CALENDARIZE_PERCENTAGES,H55:J55)*I$81*'2'!COMP_FX,"N/A") -> 5066.4 | I15: =IF(J$80>0,SUMPRODUCT('2'!COMP_CALENDARIZE_PERCENTAGES,I55:K55)*J$81*'2'!COMP_FX,"N/A") -> 5298.7 | J15: =IF(K$80>0,SUMPRODUCT('2'!COMP_CALENDARIZE_PERCENTAGES,J55:L55)*K$81*'2'!COMP_FX,"N/A") -> N/A | K15: =IF(L$80>0,SUMPRODUCT('2'!COMP_CALENDARIZE_PERCENTAGES,K55:M55)*L$81*'2'!COMP_FX,"N/A") -> N/A
B16: Last closing price | C16: 29.54 | E16: EBIT | G16: =G53*'2'!COMP_FX -> 3948 | H16: =IF(I$80>0,SUMPRODUCT('2'!COMP_CALENDARIZE_PERCENTAGES,H53:J53)*I$81*'2'!COMP_FX,"N/A") -> 4466.4 | I16: =IF(J$80>0,SUMPRODUCT('2'!COMP_CALENDARIZE_PERCENTAGES,I53:K53)*J$81*'2'!COMP_FX,"N/A") -> 4698.7 | J16: =IF(K$80>0,SUMPRODUCT('2'!COMP_CALENDARIZE_PERCENTAGES,J53:L53)*K$81*'2'!COMP_FX,"N/A") -> N/A | K16: =IF(L$80>0,SUMPRODUCT('2'!COMP_CALENDARIZE_PERCENTAGES,K53:M53)*L$81*'2'!COMP_FX,"N/A") -> N/A
B17: 52 week low | C17: 25.03 | E17: EPS | H17: =IF(I$80>0,SUMPRODUCT('2'!COMP_CALENDARIZE_PERCENTAGES,H56:J56)*I$81*'2'!COMP_FX,"N/A") -> 2.17 | I17: =IF(J$80>0,SUMPRODUCT('2'!COMP_CALENDARIZE_PERCENTAGES,I56:K56)*J$81*'2'!COMP_FX,"N/A") -> 2.31 | J17: =IF(K$80>0,SUMPRODUCT('2'!COMP_CALENDARIZE_PERCENTAGES,J56:L56)*K$81*'2'!COMP_FX,"N/A") -> N/A | K17: =IF(L$80>0,SUMPRODUCT('2'!COMP_CALENDARIZE_PERCENTAGES,K56:M56)*L$81*'2'!COMP_FX,"N/A") -> N/A
B18: 52 week high | C18: 36.12
B19: Credit rating | C19: BBB | E19: Calendarized multiples to December 31
B20: Beta | C20: 0.55 | G20: =G13 -> LTM | H20: =H13 -> 2026e | I20: =I13 -> 2027e | J20: =J13 -> 2028e | K20: =K13 -> 2029e
B21: 5 year EPS forward growth | C21: 0.065 | E21: EV / Revenue | G21: =IF(G14<>0,$H$10/G14,"N/A") -> 3.410239 | H21: =IF(ISNUMBER(H14),$H$10/H14,"N/A") -> 3.2037967 | I21: =IF(ISNUMBER(I14),$H$10/I14,"N/A") -> 3.0940262 | J21: =IF(ISNUMBER(J14),$H$10/J14,"N/A") -> N/A | K21: =IFERROR($H$10/K14,"N/A") -> N/A
B22: LTM EBIT margin | C22: =G53/G44 -> 0.24409546 | E22: EV / EBITDA | G22: =IF(G15<>0,$H$10/G15,"N/A") -> 12.175983 | H22: =IF(ISNUMBER(H15),$H$10/H15,"N/A") -> 10.886863 | I22: =IF(ISNUMBER(I15),$H$10/I15,"N/A") -> 10.409573 | J22: =IF(ISNUMBER(J15),$H$10/J15,"N/A") -> N/A | K22: =IFERROR($H$10/K15,"N/A") -> N/A
B23: Return on invested capital | C23: =G53*(1-'2'!COMP_MTR)/D39 -> 0.075943968 | E23: EV / EBIT | G23: =IF(G16<>0,$H$10/G16,"N/A") -> 13.970923 | H23: =IF(ISNUMBER(H16),$H$10/H16,"N/A") -> 12.349365 | I23: =IF(ISNUMBER(I16),$H$10/I16,"N/A") -> 11.738822 | J23: =IF(ISNUMBER(J16),$H$10/J16,"N/A") -> N/A | K23: =IFERROR($H$10/K16,"N/A") -> N/A
E24: PE | H24: =IF(ISNUMBER(H17),($C$16*'2'!COMP_FX)/H17,"N/A") -> 13.612903 | I24: =IF(ISNUMBER(I17),($C$16*'2'!COMP_FX)/I17,"N/A") -> 12.787879 | J24: =IF(ISNUMBER(J17),($C$16*'2'!COMP_FX)/J17,"N/A") -> N/A | K24: =IFERROR(($C$16*'2'!COMP_FX)/K17,"N/A") -> N/A
E25: P / BV | G25: =D36/D37 -> 1.5994395
E26: Total debt / LTM EBITDA | G26: =IF(G15=0,"N/A",H7/G15) -> 3.7172185
A28: Enterprise value calculation (home currency) | M28: Share options and RSUs
M29: Tranche | N29: Number | O29: Strike | P29: New shares
B30: Equity valuation | E30: Financial liabilities calculation | H30: Financial assets calculation | M30: Options | N30: 0 | O30: 0 | P30: =MAX(('2'!COMP_SHAREPRICE-O30)/'2'!COMP_SHAREPRICE*N30,0) -> 0
B31: Shares outstanding as of | D31: 45953 | E31: Debt - short term | G31: 2285 | H31: Cash and ST investments | J31: =516+53 -> 569 | M31: Performance share units | N31: 0.461726 | O31: 0 | P31: =MAX(('2'!COMP_SHAREPRICE-O31)/'2'!COMP_SHAREPRICE*N31,0) -> 0.461726
B32: Basic shares outstanding | D32: 1358.5831 | E32: Finance lease liabilities | G32: 150 | H32: Marketable securities | J32: 0 | M32: Time based RSUs | N32: 12.119846 | O32: 0 | P32: =MAX(('2'!COMP_SHAREPRICE-O32)/'2'!COMP_SHAREPRICE*N32,0) -> 12.119846
B33: Other adjustments | D33: 0 | E33: Finance lease liabilities | G33: 704 | H33: Equity method investments | J33: 1617 | M33: Tranche 4 | N33: 0 | O33: 0 | P33: =MAX(('2'!COMP_SHAREPRICE-O33)/'2'!COMP_SHAREPRICE*N33,0) -> 0
B34: Dilution from share options | D34: =P38 -> 12.581572 | E34: Debt - long term | G34: 13531 | H34: Other | J34: 0 | M34: Tranche 5 | N34: 0 | O34: 0 | P34: =MAX(('2'!COMP_SHAREPRICE-O34)/'2'!COMP_SHAREPRICE*N34,0) -> 0
B35: Diluted shares outstanding | D35: =SUM(D32:D34) -> 1371.1647 | E35: Structured payables | G35: 30 | H35: Other | J35: 0 | M35: Tranche 6 | N35: 0 | O35: 0 | P35: =MAX(('2'!COMP_SHAREPRICE-O35)/'2'!COMP_SHAREPRICE*N35,0) -> 0
B36: Diluted equity value | D36: =D35*'2'!COMP_SHAREPRICE -> 40504.205 | E36: Unamortized debt discount / original issue discount | G36: 139 | H36: Other | J36: 0 | M36: Tranche 7 | N36: 0 | O36: 0 | P36: =MAX(('2'!COMP_SHAREPRICE-O36)/'2'!COMP_SHAREPRICE*N36,0) -> 0
B37: Shareholders' equity | D37: 25324 | E37: NCI | G37: 0 | H37: Other | J37: 0 | M37: Tranche 8 | N37: 0 | O37: 0 | P37: =MAX(('2'!COMP_SHAREPRICE-O37)/'2'!COMP_SHAREPRICE*N37,0) -> 0
B38: Net debt and other adjustments | D38: =G39-J39 -> 14653 | M38: Total | P38: =SUM(P30:P37) -> 12.581572
B39: Invested capital | D39: =D37+D38 -> 39977 | E39: Total financial liabilities | G39: =SUM(G31:G37) -> 16839 | H39: Total financial assets | J39: =SUM(J31:J37) -> 2186
A41: Earnings (home currency) | I41: Consensus estimates
C42: Annual | D42: Last 9 months 2024 | E42: Last 9 months 2025 | F42: Other adjustments | G42: Adj. LTM | H42: Fiscal Year | I42: FY +1 | J42: FY +2 | K42: FY +3 | L42: FY +4
B43: Date | C43: =C11 -> 45657 | D43: 45565 | E43: 45930 | G43: =C13 -> 45930 | H43: =C43 -> 45657 | I43: =EDATE(C43,12) -> 46022 | J43: =EDATE(I43,12) -> 46387 | K43: =EDATE(J43,12) -> 46752 | L43: =EDATE(K43,12) -> 47118
...

Sheet 3
A1: Monster Beverage
E2: Analyst name | G2: Amgad Bashir
A4: Key data | E4: Enterprise value summary
B5: Ticker | C5: MNST-US | E5: ="Enterprise value calculation in "&MAIN_CURRENCY&" MM" -> Enterprise value calculation in USD MM
B6: Country | C6: United States | E6: + Diluted equity value | H6: =D36*'3'!COMP_FX -> 83024.655
B7: Analysis date | C7: =ANALYSIS_DATE -> 46076 | E7: + Debt | H7: =SUM(G31:G33)*'3'!COMP_FX -> 0
B8: Calendarize to | C8: =Trading_comps!D5 -> 46022 | E8: - Cash and ST investments | H8: =SUM(J31:J32)*'3'!COMP_FX -> 2579.33
B9: Currency / FX | C9: =MAIN_CURRENCY -> USD | E9: - Other adjustments | H9: =(SUM(J33:J37)-SUM(G34:G37))*'3'!COMP_FX -> 359.174
B10: Marginal tax rate | C10: 0.21 | E10: = Enterprise value | H10: ='3'!COMP_EQ_VALUE+'3'!TOTAL_DEBT-H8-H9 -> 80086.151
B11: Historical year end | C11: 45657
B12: Last filing date US format | C12: 09/30/2025 | E12: Calendarized key numbers
B13: Last filing date Intl format | C13: =DATE(RIGHT(C12,4),LEFT(C12,2),MID(C12,4,2)) -> 45930 | E13: ="Numbers in "&MAIN_CURRENCY&" MM" -> Numbers in USD MM | G13: LTM | H13: =YEAR($C$8)+1&"e" -> 2026e | I13: =YEAR($C$8)+2&"e" -> 2027e | J13: =YEAR($C$8)+3&"e" -> 2028e | K13: =YEAR($C$8)+4&"e" -> 2029e
B14: Home currency | C14: USD | E14: Revenue | G14: =G44*'3'!COMP_FX -> 7975.331 | H14: =IF(I$80>0,SUMPRODUCT('3'!COMP_CALENDARIZE_PERCENTAGES,H44:J44)*I$81*'3'!COMP_FX,"N/A") -> 9006.9 | I14: =IF(J$80>0,SUMPRODUCT('3'!COMP_CALENDARIZE_PERCENTAGES,I44:K44)*J$81*'3'!COMP_FX,"N/A") -> 9819.6 | J14: =IF(K$80>0,SUMPRODUCT('3'!COMP_CALENDARIZE_PERCENTAGES,J44:L44)*K$81*'3'!COMP_FX,"N/A") -> N/A | K14: =IF(L$80>0,SUMPRODUCT('3'!COMP_CALENDARIZE_PERCENTAGES,K44:M44)*L$81*'3'!COMP_FX,"N/A") -> N/A
B15: FX rate | C15: 1 | E15: EBITDA | G15: =G55*'3'!COMP_FX -> 2552.979 | H15: =IF(I$80>0,SUMPRODUCT('3'!COMP_CALENDARIZE_PERCENTAGES,H55:J55)*I$81*'3'!COMP_FX,"N/A") -> 2914.6 | I15: =IF(J$80>0,SUMPRODUCT('3'!COMP_CALENDARIZE_PERCENTAGES,I55:K55)*J$81*'3'!COMP_FX,"N/A") -> 3212.8 | J15: =IF(K$80>0,SUMPRODUCT('3'!COMP_CALENDARIZE_PERCENTAGES,J55:L55)*K$81*'3'!COMP_FX,"N/A") -> N/A | K15: =IF(L$80>0,SUMPRODUCT('3'!COMP_CALENDARIZE_PERCENTAGES,K55:M55)*L$81*'3'!COMP_FX,"N/A") -> N/A
